Workbook

Sheet Entry
A1: SPY SHORT STRADDLE - IMPLIED vs REALIZED
A2: Blue/yellow cells are inputs you fill in. Black cells are formulas — do not overwrite them.
A4: POSITION
A5: Underlying | B5: SPY
A6: Structure | B6: Short straddle, 1 call + 1 put (sold)
A7: Strike | B7: 775
A8: Expiration | B8: 46325
A9: Contracts per leg | B9: -1
A10: Entry date | B10: 46300 | C10: fill in: trade date
A11: Spot at fill | B11: 772.25 | C11: SPY price at the moment of fill
A12: DTE at entry (calendar) | B12: =IF($B$10="","",$B$8-$B$10)
A13: Credit per straddle | B13: 20.05 | C13: from order confirmation
A14: Fees | B14: 0.2
A15: Net credit (negative = received) | B15: =$B$13*$B$9*100+$B$14
A17: ENTRY GREEKS & IV (pull from the Sep 25 chain, not the Sep 18 chain)
A18: Call IV | B18: 0.1249 | C18: enter as 12.8% or 0.128
A19: Put IV | B19: 0.1246
A20: ATM IV (average) | B20: =IF(COUNT($B$18:$B$19)=0,"",AVERAGE($B$18:$B$19)) | C20: this is the number the whole test runs against
A21: Call delta | B21: 0.4966
A22: Put delta (negative) | B22: -0.5035
A23: Net delta per straddle | B23: =IF(COUNT($B$21:$B$22)<2,"",$B$21+$B$22) | C23: the ATM residual — expect a small positive number
A24: Position delta | B24: =IF($B$23="","",$B$23*$B$9)
A25: Position gamma | B25: -3.164
A26: Position theta ($/day) | B26: 39.95
A27: Position vega ($/vol pt) | B27: -161.25
A29: DERIVED — THE BAR
A30: Implied daily move (%) | B30: =IF($B$20="","",$B$20/SQRT(252)) | C30: ATM IV / SQRT(252) — the daily bar to beat
A31: Implied daily move (pts) | B31: =IF(OR($B$30="",$B$11=""),"",$B$30*$B$11)
A32: Implied move to expiry (%) | B32: =IF(OR($B$20="",$B$12=""),"",$B$20*SQRT($B$12/365))
A33: Upper breakeven (loss above) | B33: =$B$7+$B$13
A34: Lower breakeven (loss below) | B34: =$B$7-$B$13
A35: Breakeven move (%) | B35: =IF($B$11="","",$B$13/$B$11) | C35: what you paid, as a % move
A37: THESIS & RULES (write these BEFORE you know anything)
A38: Thesis (one sentence)
A39: Morph rule — go bullish if...
A40: Morph rule — go bearish if...
A41: Exit rule (date / P&L / IV level) | B41: exit if p&l reaches -2000
A42: Fill convention used | B42: Limit at combo mid + $0.03
A44: Assumptions: strike, expiry, debit ($23.53) and fees ($0.20) taken from the user's order confirmation. Realized vol uses zero-mean RMS of simple close-to-close returns, annualized by SQRT(252). Daily bar uses the entry ATM IV held constant.

Sheet Daily Log
A1: DAILY MARK — mark at the same time every day. Blue are entries
A2: Date | B2: DTE | C2: SPY Close | D2: Return | E2: |Return| | F2: Daily Bar | G2: Beat? | H2: Call IV | I2: Put IV | J2: ATM IV | K2: Straddle Mark | L2: P&L ($) | M2: Realized Vol (ann) | N2: RV − IV | O2: Gamma (sh/$1) | P2: Theta ($/day) | Q2: Vega ($/pt) | R2: Notes | S2: Call Mid | T2: Put Mid | U2: Delta (sh)
A3: =Entry!$B$10 | B3: =IF($A3="","",Entry!$B$8-$A3) | C3: =Entry!$B$11 | K3: =Entry!$B$13 | R3: ENTRY — row zero
A4: 46301 | B4: =Entry!$B$8-$A4 | C4: 779.09 | D4: =IF(OR($C4="",$C3=""),"",$C4/$C3-1) | E4: =IF(ISNUMBER($D4),ABS($D4),"") | F4: =IF(Entry!$B$30="","",Entry!$B$30) | G4: =IF(AND(ISNUMBER($E4),ISNUMBER($F4)),IF($E4>$F4,"YES","no"),"") | H4: 0.1279 | I4: 0.1232 | J4: =IF(COUNT($H4:$I4)=0,"",AVERAGE($H4:$I4)) | K4: 20.53 | L4: =IF($K4="","",($K4-Entry!$B$13)*Entry!$B$9*100) | M4: =IF(COUNT($D$4:$D4)=0,"",SQRT(SUMSQ($D$4:$D4)/COUNT($D$4:$D4))*SQRT(252)) | N4: =IF(OR($M4="",Entry!$B$20=""),"",$M4-Entry!$B$20) | O4: -3.08 | P4: 41.83 | Q4: -154.05 | S4: 13.51 | T4: 7.02 | U4: -20.6
A5: 46302 | B5: =Entry!$B$8-$A5 | C5: 777.22 | D5: =IF(OR($C5="",$C4=""),"",$C5/$C4-1) | E5: =IF(ISNUMBER($D5),ABS($D5),"") | F5: =IF(Entry!$B$30="","",Entry!$B$30) | G5: =IF(AND(ISNUMBER($E5),ISNUMBER($F5)),IF($E5>$F5,"YES","no"),"") | H5: 0.1243 | I5: 0.1221 | J5: =IF(COUNT($H5:$I5)=0,"",AVERAGE($H5:$I5)) | K5: 19.42 | L5: =IF($K5="","",($K5-Entry!$B$13)*Entry!$B$9*100) | M5: =IF(COUNT($D$4:$D5)=0,"",SQRT(SUMSQ($D$4:$D5)/COUNT($D$4:$D5))*SQRT(252)) | N5: =IF(OR($M5="",Entry!$B$20=""),"",$M5-Entry!$B$20) | O5: -3.26 | P5: 42.03 | Q5: -152.9 | S5: 11.88 | T5: 7.54 | U5: -15
A6: 46303 | B6: =Entry!$B$8-$A6 | C6: 773.93 | D6: =IF(OR($C6="",$C5=""),"",$C6/$C5-1) | E6: =IF(ISNUMBER($D6),ABS($D6),"") | F6: =IF(Entry!$B$30="","",Entry!$B$30) | G6: =IF(AND(ISNUMBER($E6),ISNUMBER($F6)),IF($E6>$F6,"YES","no"),"") | H6: 0.1239 | I6: 0.1179 | J6: =IF(COUNT($H6:$I6)=0,"",AVERAGE($H6:$I6)) | K6: 18.33 | L6: =IF($K6="","",($K6-Entry!$B$13)*Entry!$B$9*100) | M6: =IF(COUNT($D$4:$D6)=0,"",SQRT(SUMSQ($D$4:$D6)/COUNT($D$4:$D6))*SQRT(252)) | N6: =IF(OR($M6="",Entry!$B$20=""),"",$M6-Entry!$B$20) | O6: -3.47 | P6: 41.74 | Q6: -151.42 | S6: 9.79 | T6: 8.54 | U6: -4
A7: 46304 | B7: =Entry!$B$8-$A7 | C7: 778.57 | D7: =IF(OR($C7="",$C6=""),"",$C7/$C6-1) | E7: =IF(ISNUMBER($D7),ABS($D7),"") | F7: =IF(Entry!$B$30="","",Entry!$B$30) | G7: =IF(AND(ISNUMBER($E7),ISNUMBER($F7)),IF($E7>$F7,"YES","no"),"") | H7: 0.1161 | I7: 0.1178 | J7: =IF(COUNT($H7:$I7)=0,"",AVERAGE($H7:$I7)) | K7: 17.89 | L7: =IF($K7="","",($K7-Entry!$B$13)*Entry!$B$9*100) | M7: =IF(COUNT($D$4:$D7)=0,"",SQRT(SUMSQ($D$4:$D7)/COUNT($D$4:$D7))*SQRT(252)) | N7: =IF(OR($M7="",Entry!$B$20=""),"",$M7-Entry!$B$20) | O7: -3.53 | P7: 41.67 | Q7: -144.06 | S7: 11.56 | T7: 6.33 | U7: -20.5
A8: 46307 | B8: =Entry!$B$8-$A8 | C8: 778.1 | D8: =IF(OR($C8="",$C7=""),"",$C8/$C7-1) | E8: =IF(ISNUMBER($D8),ABS($D8),"") | F8: =IF(Entry!$B$30="","",Entry!$B$30) | G8: =IF(AND(ISNUMBER($E8),ISNUMBER($F8)),IF($E8>$F8,"YES","no"),"") | H8: 0.1187 | I8: 0.1179 | J8: =IF(COUNT($H8:$I8)=0,"",AVERAGE($H8:$I8)) | K8: 16.68 | L8: =IF($K8="","",($K8-Entry!$B$13)*Entry!$B$9*100) | M8: =IF(COUNT($D$4:$D8)=0,"",SQRT(SUMSQ($D$4:$D8)/COUNT($D$4:$D8))*SQRT(252)) | N8: =IF(OR($M8="",Entry!$B$20=""),"",$M8-Entry!$B$20) | O8: -3.79 | P8: 45.46 | Q8: -133.95 | S8: 10.68 | T8: 6 | U8: -19
A9: 46308 | B9: =Entry!$B$8-$A9 | C9: 778.01 | D9: =IF(OR($C9="",$C8=""),"",$C9/$C8-1) | E9: =IF(ISNUMBER($D9),ABS($D9),"") | F9: =IF(Entry!$B$30="","",Entry!$B$30) | G9: =IF(AND(ISNUMBER($E9),ISNUMBER($F9)),IF($E9>$F9,"YES","no"),"") | H9: 0.1219 | I9: 0.1178 | J9: =IF(COUNT($H9:$I9)=0,"",AVERAGE($H9:$I9)) | K9: 16.4 | L9: =IF($K9="","",($K9-Entry!$B$13)*Entry!$B$9*100) | M9: =IF(COUNT($D$4:$D9)=0,"",SQRT(SUMSQ($D$4:$D9)/COUNT($D$4:$D9))*SQRT(252)) | N9: =IF(OR($M9="",Entry!$B$20=""),"",$M9-Entry!$B$20) | O9: -3.86 | P9: 47.34 | Q9: -130.32 | S9: 10.56 | T9: 5.84 | U9: -18.6
A10: 46309 | B10: =Entry!$B$8-$A10 | C10: 769.67 | D10: =IF(OR($C10="",$C9=""),"",$C10/$C9-1) | E10: =IF(ISNUMBER($D10),ABS($D10),"") | F10: =IF(Entry!$B$30="","",Entry!$B$30) | G10: =IF(AND(ISNUMBER($E10),ISNUMBER($F10)),IF($E10>$F10,"YES","no"),"") | H10: 0.1202 | I10: 0.1266 | J10: =IF(COUNT($H10:$I10)=0,"",AVERAGE($H10:$I10)) | K10: 16.22 | L10: =IF($K10="","",($K10-Entry!$B$13)*Entry!$B$9*100) | M10: =IF(COUNT($D$4:$D10)=0,"",SQRT(SUMSQ($D$4:$D10)/COUNT($D$4:$D10))*SQRT(252)) | N10: =IF(OR($M10="",Entry!$B$20=""),"",$M10-Entry!$B$20) | O10: -3.95 | P10: 47.3 | Q10: -126.36 | S10: 5.92 | T10: 10.3 | U10: 14.8
A11: 46310 | B11: =Entry!$B$8-$A11 | C11: 773.09 | D11: =IF(OR($C11="",$C10=""),"",$C11/$C10-1) | E11: =IF(ISNUMBER($D11),ABS($D11),"") | F11: =IF(Entry!$B$30="","",Entry!$B$30) | G11: =IF(AND(ISNUMBER($E11),ISNUMBER($F11)),IF($E11>$F11,"YES","no"),"") | H11: 0.1094 | I11: 0.1291 | J11: =IF(COUNT($H11:$I11)=0,"",AVERAGE($H11:$I11)) | K11: 14.93 | L11: =IF($K11="","",($K11-Entry!$B$13)*Entry!$B$9*100) | M11: =IF(COUNT($D$4:$D11)=0,"",SQRT(SUMSQ($D$4:$D11)/COUNT($D$4:$D11))*SQRT(252)) | N11: =IF(OR($M11="",Entry!$B$20=""),"",$M11-Entry!$B$20) | O11: -4.3 | P11: 49.39 | Q11: -125.01 | S11: 6.53 | T11: 8.4 | U11: 1.8
A12: 46311 | B12: =Entry!$B$8-$A12 | C12: 763.23 | D12: =IF(OR($C12="",$C11=""),"",$C12/$C11-1) | E12: =IF(ISNUMBER($D12),ABS($D12),"") | F12: =IF(Entry!$B$30="","",Entry!$B$30) | G12: =IF(AND(ISNUMBER($E12),ISNUMBER($F12)),IF($E12>$F12,"YES","no"),"") | H12: 0.122 | I12: 0.1352 | J12: =IF(COUNT($H12:$I12)=0,"",AVERAGE($H12:$I12)) | K12: 17.7 | L12: =IF($K12="","",($K12-Entry!$B$13)*Entry!$B$9*100) | M12: =IF(COUNT($D$4:$D12)=0,"",SQRT(SUMSQ($D$4:$D12)/COUNT($D$4:$D12))*SQRT(252)) | N12: =IF(OR($M12="",Entry!$B$20=""),"",$M12-Entry!$B$20) | O12: -3.6 | P12: 43.88 | Q12: -103.3 | S12: 3.22 | T12: 14.48 | U12: 40.8
A13: 46314 | B13: =Entry!$B$8-$A13 | C13: 766.48 | D13: =IF(OR($C13="",$C12=""),"",$C13/$C12-1) | E13: =IF(ISNUMBER($D13),ABS($D13),"") | F13: =IF(Entry!$B$30="","",Entry!$B$30) | G13: =IF(AND(ISNUMBER($E13),ISNUMBER($F13)),IF($E13>$F13,"YES","no"),"") | H13: 0.133 | I13: 0.1234 | J13: =IF(COUNT($H13:$I13)=0,"",AVERAGE($H13:$I13)) | K13: 15 | L13: =IF($K13="","",($K13-Entry!$B$13)*Entry!$B$9*100) | M13: =IF(COUNT($D$4:$D13)=0,"",SQRT(SUMSQ($D$4:$D13)/COUNT($D$4:$D13))*SQRT(252)) | N13: =IF(OR($M13="",Entry!$B$20=""),"",$M13-Entry!$B$20) | O13: -4.26 | P13: 53.41 | Q13: -96.7 | S13: 3.94 | T13: 11.06 | U13: 33.4
A14: 46315 | B14: =Entry!$B$8-$A14 | C14: 769.05 | D14: =IF(OR($C14="",$C13=""),"",$C14/$C13-1) | E14: =IF(ISNUMBER($D14),ABS($D14),"") | F14: =IF(Entry!$B$30="","",Entry!$B$30) | G14: =IF(AND(ISNUMBER($E14),ISNUMBER($F14)),IF($E14>$F14,"YES","no"),"") | H14: 0.1365 | I14: 0.1204 | J14: =IF(COUNT($H14:$I14)=0,"",AVERAGE($H14:$I14)) | K14: 13.72 | L14: =IF($K14="","",($K14-Entry!$B$13)*Entry!$B$9*100) | M14: =IF(COUNT($D$4:$D14)=0,"",SQRT(SUMSQ($D$4:$D14)/COUNT($D$4:$D14))*SQRT(252)) | N14: =IF(OR($M14="",Entry!$B$20=""),"",$M14-Entry!$B$20) | O14: -4.68 | P14: 60.2 | Q14: -97.03 | S14: 4.7 | T14: 9.02 | U14: 23.7
A15: 46316 | B15: =Entry!$B$8-$A15 | D15: =IF(OR($C15="",$C14=""),"",$C15/$C14-1) | E15: =IF(ISNUMBER($D15),ABS($D15),"") | F15: =IF(Entry!$B$30="","",Entry!$B$30) | G15: =IF(AND(ISNUMBER($E15),ISNUMBER($F15)),IF($E15>$F15,"YES","no"),"") | J15: =IF(COUNT($H15:$I15)=0,"",AVERAGE($H15:$I15)) | L15: =IF($K15="","",($K15-Entry!$B$13)*Entry!$B$9*100) | M15: =IF(COUNT($D$4:$D15)=0,"",SQRT(SUMSQ($D$4:$D15)/COUNT($D$4:$D15))*SQRT(252)) | N15: =IF(OR($M15="",Entry!$B$20=""),"",$M15-Entry!$B$20)
A16: 46317 | B16: =Entry!$B$8-$A16 | C16: 763.96 | D16: =IF(OR($C16="",$C15=""),"",$C16/$C15-1) | E16: =IF(ISNUMBER($D16),ABS($D16),"") | F16: =IF(Entry!$B$30="","",Entry!$B$30) | G16: =IF(AND(ISNUMBER($E16),ISNUMBER($F16)),IF($E16>$F16,"YES","no"),"") | H16: 0.1471 | I16: 0.1417 | J16: =IF(COUNT($H16:$I16)=0,"",AVERAGE($H16:$I16)) | K16: 15.64 | L16: =IF($K16="","",($K16-Entry!$B$13)*Entry!$B$9*100) | M16: =IF(COUNT($D$4:$D16)=0,"",SQRT(SUMSQ($D$4:$D16)/COUNT($D$4:$D16))*SQRT(252)) | N16: =IF(OR($M16="",Entry!$B$20=""),"",$M16-Entry!$B$20) | O16: -4.03 | P16: 63.15 | Q16: -74.47 | S16: 2.74 | T16: 12.9 | U16: 46.5
A17: 46318 | B17: =Entry!$B$8-$A17 | C17: 759.97 | D17: =IF(OR($C17="",$C16=""),"",$C17/$C16-1) | E17: =IF(ISNUMBER($D17),ABS($D17),"") | F17: =IF(Entry!$B$30="","",Entry!$B$30) | G17: =IF(AND(ISNUMBER($E17),ISNUMBER($F17)),IF($E17>$F17,"YES","no"),"") | H17: 0.1422 | I17: 0.1237 | J17: =IF(COUNT($H17:$I17)=0,"",AVERAGE($H17:$I17)) | K17: 16.71 | L17: =IF($K17="","",($K17-Entry!$B$13)*Entry!$B$9*100) | M17: =IF(COUNT($D$4:$D17)=0,"",SQRT(SUMSQ($D$4:$D17)/COUNT($D$4:$D17))*SQRT(252)) | N17: =IF(OR($M17="",Entry!$B$20=""),"",$M17-Entry!$B$20) | O17: -3.4 | P17: 41.84 | Q17: -50.04 | S17: 1.37 | T17: 15.34 | U17: 69
A18: 46321 | B18: =Entry!$B$8-$A18 | C18: 765.37 | D18: =IF(OR($C18="",$C17=""),"",$C18/$C17-1) | E18: =IF(ISNUMBER($D18),ABS($D18),"") | F18: =IF(Entry!$B$30="","",Entry!$B$30) | G18: =IF(AND(ISNUMBER($E18),ISNUMBER($F18)),IF($E18>$F18,"YES","no"),"") | H18: 0.1451 | I18: 0.153 | J18: =IF(COUNT($H18:$I18)=0,"",AVERAGE($H18:$I18)) | K18: 12.32 | L18: =IF($K18="","",($K18-Entry!$B$13)*Entry!$B$9*100) | M18: =IF(COUNT($D$4:$D18)=0,"",SQRT(SUMSQ($D$4:$D18)/COUNT($D$4:$D18))*SQRT(252)) | N18: =IF(OR($M18="",Entry!$B$20=""),"",$M18-Entry!$B$20) | O18: -4.98 | P18: 84.07 | Q18: -47.67 | S18: 1.42 | T18: 10.9 | U18: 55.6
A19: 46322 | B19: =Entry!$B$8-$A19 | C19: 769.66 | D19: =IF(OR($C19="",$C18=""),"",$C19/$C18-1) | E19: =IF(ISNUMBER($D19),ABS($D19),"") | F19: =IF(Entry!$B$30="","",Entry!$B$30) | G19: =IF(AND(ISNUMBER($E19),ISNUMBER($F19)),IF($E19>$F19,"YES","no"),"") | H19: 0.1545 | I19: 0.1389 | J19: =IF(COUNT($H19:$I19)=0,"",AVERAGE($H19:$I19)) | K19: 9.18 | L19: =IF($K19="","",($K19-Entry!$B$13)*Entry!$B$9*100) | M19: =IF(COUNT($D$4:$D19)=0,"",SQRT(SUMSQ($D$4:$D19)/COUNT($D$4:$D19))*SQRT(252)) | N19: =IF(OR($M19="",Entry!$B$20=""),"",$M19-Entry!$B$20) | O19: -6.93 | P19: 117.48 | Q19: -49.36 | S19: 2.24 | T19: 6.94 | U19: 37.6
A20: 46323 | B20: =Entry!$B$8-$A20 | C20: 772.31 | D20: =IF(OR($C20="",$C19=""),"",$C20/$C19-1) | E20: =IF(ISNUMBER($D20),ABS($D20),"") | F20: =IF(Entry!$B$30="","",Entry!$B$30) | G20: =IF(AND(ISNUMBER($E20),ISNUMBER($F20)),IF($E20>$F20,"YES","no"),"") | H20: 0.1412 | I20: 0.1576 | J20: =IF(COUNT($H20:$I20)=0,"",AVERAGE($H20:$I20)) | K20: 7.12 | L20: =IF($K20="","",($K20-Entry!$B$13)*Entry!$B$9*100) | M20: =IF(COUNT($D$4:$D20)=0,"",SQRT(SUMSQ($D$4:$D20)/COUNT($D$4:$D20))*SQRT(252)) | N20: =IF(OR($M20="",Entry!$B$20=""),"",$M20-Entry!$B$20) | O20: -8.98 | P20: 161.35 | Q20: -43.73 | S20: 2.12 | T20: 5 | U20: 22.8
A21: 46324 | B21: =Entry!$B$8-$A21 | C21: 769.36 | D21: =IF(OR($C21="",$C20=""),"",$C21/$C20-1) | E21: =IF(ISNUMBER($D21),ABS($D21),"") | F21: =IF(Entry!$B$30="","",Entry!$B$30) | G21: =IF(AND(ISNUMBER($E21),ISNUMBER($F21)),IF($E21>$F21,"YES","no"),"") | H21: 0.0938 | I21: 0.3852 | J21: =IF(COUNT($H21:$I21)=0,"",AVERAGE($H21:$I21)) | K21: 9.5 | L21: =IF($K21="","",($K21-Entry!$B$13)*Entry!$B$9*100) | M21: =IF(COUNT($D$4:$D21)=0,"",SQRT(SUMSQ($D$4:$D21)/COUNT($D$4:$D21))*SQRT(252)) | N21: =IF(OR($M21="",Entry!$B$20=""),"",$M21-Entry!$B$20) | O21: -6.04 | P21: 312.36 | Q21: -20.63 | S21: 0.12 | T21: 9.38 | U21: 56.4
A22: 46325 | B22: =Entry!$B$8-$A22 | C22: 755.72 | D22: =IF(OR($C22="",$C21=""),"",$C22/$C21-1) | E22: =IF(ISNUMBER($D22),ABS($D22),"") | F22: =IF(Entry!$B$30="","",Entry!$B$30) | G22: =IF(AND(ISNUMBER($E22),ISNUMBER($F22)),IF($E22>$F22,"YES","no"),"") | J22: =IF(COUNT($H22:$I22)=0,"",AVERAGE($H22:$I22)) | L22: =IF($K22="","",($K22-Entry!$B$13)*Entry!$B$9*100) | M22: =IF(COUNT($D$4:$D22)=0,"",SQRT(SUMSQ($D$4:$D22)/COUNT($D$4:$D22))*SQRT(252)) | N22: =IF(OR($M22="",Entry!$B$20=""),"",$M22-Entry!$B$20) | S22: 0 | T22: 18.24
B23: =Entry!$B$8-$A23 | D23: =IF(OR($C23="",$C22=""),"",$C23/$C22-1) | E23: =IF(ISNUMBER($D23),ABS($D23),"") | F23: =IF(Entry!$B$30="","",Entry!$B$30) | G23: =IF(AND(ISNUMBER($E23),ISNUMBER($F23)),IF($E23>$F23,"YES","no"),"") | J23: =IF(COUNT($H23:$I23)=0,"",AVERAGE($H23:$I23)) | L23: =IF($K23="","",($K23-Entry!$B$13)*Entry!$B$9*100) | M23: =IF(COUNT($D$4:$D23)=0,"",SQRT(SUMSQ($D$4:$D23)/COUNT($D$4:$D23))*SQRT(252)) | N23: =IF(OR($M23="",Entry!$B$20=""),"",$M23-Entry!$B$20)
B24: =Entry!$B$8-$A24 | D24: =IF(OR($C24="",$C23=""),"",$C24/$C23-1) | E24: =IF(ISNUMBER($D24),ABS($D24),"") | F24: =IF(Entry!$B$30="","",Entry!$B$30) | G24: =IF(AND(ISNUMBER($E24),ISNUMBER($F24)),IF($E24>$F24,"YES","no"),"") | J24: =IF(COUNT($H24:$I24)=0,"",AVERAGE($H24:$I24)) | L24: =IF($K24="","",($K24-Entry!$B$13)*Entry!$B$9*100) | M24: =IF(COUNT($D$4:$D24)=0,"",SQRT(SUMSQ($D$4:$D24)/COUNT($D$4:$D24))*SQRT(252)) | N24: =IF(OR($M24="",Entry!$B$20=""),"",$M24-Entry!$B$20)
B25: =Entry!$B$8-$A25 | D25: =IF(OR($C25="",$C24=""),"",$C25/$C24-1) | E25: =IF(ISNUMBER($D25),ABS($D25),"") | F25: =IF(Entry!$B$30="","",Entry!$B$30) | G25: =IF(AND(ISNUMBER($E25),ISNUMBER($F25)),IF($E25>$F25,"YES","no"),"") | J25: =IF(COUNT($H25:$I25)=0,"",AVERAGE($H25:$I25)) | L25: =IF($K25="","",($K25-Entry!$B$13)*Entry!$B$9*100) | M25: =IF(COUNT($D$4:$D25)=0,"",SQRT(SUMSQ($D$4:$D25)/COUNT($D$4:$D25))*SQRT(252)) | N25: =IF(OR($M25="",Entry!$B$20=""),"",$M25-Entry!$B$20)
B26: =Entry!$B$8-$A26 | D26: =IF(OR($C26="",$C25=""),"",$C26/$C25-1) | E26: =IF(ISNUMBER($D26),ABS($D26),"") | F26: =IF(Entry!$B$30="","",Entry!$B$30) | G26: =IF(AND(ISNUMBER($E26),ISNUMBER($F26)),IF($E26>$F26,"YES","no"),"") | J26: =IF(COUNT($H26:$I26)=0,"",AVERAGE($H26:$I26)) | L26: =IF($K26="","",($K26-Entry!$B$13)*Entry!$B$9*100) | M26: =IF(COUNT($D$4:$D26)=0,"",SQRT(SUMSQ($D$4:$D26)/COUNT($D$4:$D26))*SQRT(252)) | N26: =IF(OR($M26="",Entry!$B$20=""),"",$M26-Entry!$B$20)
A28: SUMMARY
A29: Days logged | B29: =COUNT($D$4:$D$26)
A30: Days above the bar | B30: =COUNTIF($G$4:$G$26,"YES")
A31: Hit rate | B31: =IF(COUNT($D$4:$D$26)=0,"",COUNTIF($G$4:$G$26,"YES")/COUNT($D$4:$D$26))
A32: Realized vol to date (ann) | B32: =IF(COUNT($D$4:$D$26)=0,"",SQRT(SUMSQ($D$4:$D$26)/COUNT($D$4:$D$26))*SQRT(252))
A33: Implied vol paid at entry | B33: =IF(Entry!$B$20="","",Entry!$B$20)
A34: Realized − Implied | B34: =IF(OR($B32="",$B33=""),"",$B32-$B33)
A35: Latest mark-to-market P&L | B35: =IFERROR(LOOKUP(9.99E+307,$L$4:$L$26),"")
A37: Note: 'Realized − Implied' and mark-to-market P&L will not agree day to day. Vega moves the P&L independently of realized movement. Where they diverge is the interesting part — log why in Notes.
A39: EXAMPLE ROW — format reference only, not part of the log. Do not edit.
A40: 46259 | B40: 31 | C40: 769.1 | D40: 0.0031 | E40: 0.0031 | F40: 0.0081 | G40: no | H40: 0.1265 | I40: 0.1265 | J40: 0.1265 | K40: 22.9 | L40: -1260 | M40: 0.0492 | N40: -0.0788 | R40: quiet tape, theta day

Sheet Position
A1: POSITION — LEGS & ASSUMPTIONS (read by straddle_tool.py; keep this layout)
A2: Yellow cells are inputs. Legs start at row 6, one per row, until a blank.
A4: LEGS
A5: Right (C/P) | B5: Strike | C5: Expiry | D5: Contracts (signed)
A6: C | B6: 775 | C6: 46325 | D6: -1
A7: P | B7: 775 | C7: 46325 | D7: -1
A9: ASSUMPTIONS
A10: Risk-free rate (annual) | B10: 0.04 | C10: set from ~1-month T-bill yield
A11: Dividend per share ($) | B11: 0 | C11: ESTIMATE — update when SPY declares (usually mid-Sep)
A12: Ex-dividend date
A13: Contract multiplier | B13: 100
A15: Entry debit & contract count for P&L are read from the Entry tab (B13 × B9 × 100).

Sheet Greek History
A1: GREEK HISTORY — what each leg contributes to the position Greeks, mark by mark. Rebuilt by straddle_tool.py on every `mark`; anything typed here is lost.
A2: Units: value $ · delta share-equivalents · gamma sh/$1 · theta $/calendar day · vega $/vol pt. The entry row is the model at the Entry-tab IVs.
A4: Date | B4: DTE | C4: Spot | D4: Leg | E4: Qty | F4: IV | G4: Price/sh | H4: Value ($) | I4: P&L vs entry ($) | J4: Delta (sh) | K4: Gamma (sh/$1) | L4: Theta ($/day) | M4: Vega ($/pt) | N4: Source
A5: 46300 | B5: 25 | C5: 772.25 | D5: C 775 2026-10-30 | E5: -1 | F5: 0.1249 | G5: 9.7625469 | H5: -976.25469 | J5: -49.657391 | K5: -1.5803385 | L5: 24.235919 | M5: -80.626079 | N5: entry
A6: 46300 | B6: 25 | C6: 772.25 | D6: P 775 2026-10-30 | E6: -1 | F6: 0.1246 | G6: 10.367977 | H6: -1036.7977 | J6: 50.34657 | K6: -1.5841421 | L6: 15.717543 | M6: -80.62601 | N6: entry
A7: 46300 | B7: 25 | C7: 772.25 | D7: POSITION | H7: -2013.0524 | I7: -8.0524267 | J7: 0.68917946 | K7: -3.1644806 | L7: 39.953462 | M7: -161.25209 | N7: entry
A9: 46301 | B9: 24 | C9: 779.09 | D9: C 775 2026-10-30 | E9: -1 | F9: 0.12791884 | G9: 13.51 | H9: -1351 | J9: -60.143019 | K9: -1.5103609 | L9: 25.536481 | M9: -77.109674 | N9: mids
A10: 46301 | B10: 24 | C10: 779.09 | D10: P 775 2026-10-30 | E10: -1 | F10: 0.12318888 | G10: 7.02 | H10: -702 | J10: 39.524119 | K10: -1.5648176 | L10: 16.293601 | M10: -76.93587 | N10: mids
A11: 46301 | B11: 24 | C11: 779.09 | D11: POSITION | H11: -2053 | I11: -48 | J11: -20.618899 | K11: -3.0751784 | L11: 41.830082 | M11: -154.04554 | N11: mids
A13: 46302 | B13: 23 | C13: 777.22 | D13: C 775 2026-10-30 | E13: -1 | F13: 0.12433854 | G13: 11.88 | H13: -1188 | J13: -57.456405 | K13: -1.6157252 | L13: 25.433819 | M13: -76.470895 | N13: mids
A14: 46302 | B14: 23 | C14: 777.22 | D14: P 775 2026-10-30 | E14: -1 | F14: 0.1221275 | G14: 7.54 | H14: -754 | J14: 42.432166 | K14: -1.644091 | L14: 16.594893 | M14: -76.429713 | N14: mids
A15: 46302 | B15: 23 | C15: 777.22 | D15: POSITION | H15: -1942 | I15: 63 | J15: -15.024238 | K15: -3.2598161 | L15: 42.028712 | M15: -152.90061 | N15: mids
A17: 46303 | B17: 22 | C17: 773.93 | D17: C 775 2026-10-30 | E17: -1 | F17: 0.12389891 | G17: 9.79 | H17: -979 | J17: -51.956004 | K17: -1.6925971 | L17: 25.61843 | M17: -75.710172 | N17: mids
A18: 46303 | B18: 22 | C18: 773.93 | D18: P 775 2026-10-30 | E18: -1 | F18: 0.11790542 | G18: 8.54 | H18: -854 | J18: 48.004769 | K18: -1.7785502 | L18: 16.12175 | M18: -75.70648 | N18: mids
A19: 46303 | B19: 22 | C19: 773.93 | D19: POSITION | H19: -1833 | I19: 172 | J19: -3.9512349 | K19: -3.4711472 | L19: 41.740179 | M19: -151.41665 | N19: mids
A21: 46304 | B21: 21 | C21: 778.57 | D21: C 775 2026-10-30 | E21: -1 | F21: 0.11612072 | G21: 11.56 | H21: -1156 | J21: -60.316819 | K21: -1.7778047 | L21: 24.925344 | M21: -71.99719 | N21: mids
A22: 46304 | B22: 21 | C22: 778.57 | D22: P 775 2026-10-30 | E22: -1 | F22: 0.1178077 | G22: 6.33 | H22: -633 | J22: 39.812145 | K22: -1.7538704 | L22: 16.746123 | M22: -72.059781 | N22: mids
A23: 46304 | B23: 21 | C23: 778.57 | D23: POSITION | H23: -1789 | I23: 216 | J23: -20.504674 | K23: -3.5316751 | L23: 41.671467 | M23: -144.05697 | N23: mids
A25: 46307 | B25: 18 | C25: 778.1 | D25: C 775 2026-10-30 | E25: -1 | F25: 0.11870724 | G25: 10.68 | H25: -1068 | J25: -59.461971 | K25: -1.8899822 | L25: 27.041544 | M25: -66.98621 | N25: mids
A26: 46307 | B26: 18 | C26: 778.1 | D26: P 775 2026-10-30 | E26: -1 | F26: 0.11791979 | G26: 6 | H26: -600 | J26: 40.482852 | K26: -1.901953 | L26: 18.416389 | M26: -66.963313 | N26: mids
A27: 46307 | B27: 18 | C27: 778.1 | D27: POSITION | H27: -1668 | I27: 337 | J27: -18.979119 | K27: -3.7919352 | L27: 45.457933 | M27: -133.94952 | N27: mids
A29: 46308 | B29: 17 | C29: 778.01 | D29: C 775 2026-10-30 | E29: -1 | F29: 0.12188443 | G29: 10.56 | H29: -1056 | J29: -59.147598 | K29: -1.8979159 | L29: 28.306009 | M29: -65.215616 | N29: mids
A30: 46308 | B30: 17 | C30: 778.01 | D30: P 775 2026-10-30 | E30: -1 | F30: 0.11777913 | G30: 5.84 | H30: -584 | J30: 40.574446 | K30: -1.9607676 | L30: 19.029876 | M30: -65.105977 | N30: mids
A31: 46308 | B31: 17 | C31: 778.01 | D31: POSITION | H31: -1640 | I31: 365 | J31: -18.573153 | K31: -3.8586835 | L31: 47.335885 | M31: -130.32159 | N31: mids
A33: 46309 | B33: 16 | C33: 769.67 | D33: C 775 2026-10-30 | E33: -1 | F33: 0.1201607 | G33: 5.92 | H33: -592 | J33: -42.385622 | K33: -2.0226532 | L33: 27.209378 | M33: -63.113185 | N33: mids
A34: 46309 | B34: 16 | C34: 769.67 | D34: P 775 2026-10-30 | E34: -1 | F34: 0.12661387 | G34: 10.3 | H34: -1030 | J34: 57.179018 | K34: -1.9235431 | L34: 20.087877 | M34: -63.244015 | N34: mids
A35: 46309 | B35: 16 | C35: 769.67 | D35: POSITION | H35: -1622 | I35: 383 | J35: 14.793396 | K35: -3.9461963 | L35: 47.297255 | M35: -126.3572 | N35: mids
A37: 46310 | B37: 15 | C37: 773.09 | D37: C 775 2026-10-30 | E37: -1 | F37: 0.1094181 | G37: 6.53 | H37: -653 | J37: -48.961069 | K37: -2.3256499 | L37: 26.872595 | M37: -62.501727 | N37: mids
A38: 46310 | B38: 15 | C38: 773.09 | D38: P 775 2026-10-30 | E38: -1 | F38: 0.12914253 | G38: 8.4 | H38: -840 | J38: 50.732972 | K38: -1.9707803 | L38: 22.519758 | M38: -62.512377 | N38: mids
A39: 46310 | B39: 15 | C39: 773.09 | D39: POSITION | H39: -1493 | I39: 512 | J39: 1.7719037 | K39: -4.2964303 | L39: 49.392352 | M39: -125.0141 | N39: mids
A41: 46311 | B41: 14 | C41: 763.23 | D41: C 775 2026-10-30 | E41: -1 | F41: 0.12203483 | G41: 3.22 | H41: -322 | J41: -28.631958 | K41: -1.865255 | L41: 24.525866 | M41: -50.859024 | N41: mids
A42: 46311 | B42: 14 | C42: 763.23 | D42: P 775 2026-10-30 | E42: -1 | F42: 0.13515485 | G42: 14.48 | H42: -1448 | J42: 69.390786 | K42: -1.7365896 | L42: 19.350637 | M42: -52.441469 | N42: mids
A43: 46311 | B43: 14 | C43: 763.23 | D43: POSITION | H43: -1770 | I43: 235 | J43: 40.758828 | K43: -3.6018445 | L43: 43.876502 | M43: -103.30049 | N43: mids
A45: 46314 | B45: 11 | C45: 766.48 | D45: C 775 2026-10-30 | E45: -1 | F45: 0.13304933 | G45: 3.94 | H45: -394 | J45: -33.912182 | K45: -2.0676332 | L45: 32.261636 | M45: -48.706583 | N45: mids
A46: 46314 | B46: 11 | C46: 766.48 | D46: P 775 2026-10-30 | E46: -1 | F46: 0.12340723 | G46: 11.06 | H46: -1106 | J46: 67.328936 | K46: -2.1965385 | L46: 21.144784 | M46: -47.993332 | N46: mids
A47: 46314 | B47: 11 | C47: 766.48 | D47: POSITION | H47: -1500 | I47: 505 | J47: 33.416753 | K47: -4.2641717 | L47: 53.406421 | M47: -96.699915 | N47: mids
A49: 46315 | B49: 10 | C49: 769.05 | D49: C 775 2026-10-30 | E49: -1 | F49: 0.13650492 | G49: 4.7 | H49: -470 | J49: -38.923885 | K49: -2.2068377 | L49: 36.545012 | M49: -48.812944 | N49: mids
A50: 46315 | B50: 10 | C50: 769.05 | D50: P 775 2026-10-30 | E50: -1 | F50: 0.12041038 | G50: 9.02 | H50: -902 | J50: 62.617729 | K50: -2.4714901 | L50: 23.655498 | M50: -48.221318 | N50: mids
A51: 46315 | B51: 10 | C51: 769.05 | D51: POSITION | H51: -1372 | I51: 633 | J51: 23.693844 | K51: -4.6783278 | L51: 60.20051 | M51: -97.034262 | N51: mids
A53: 46317 | B53: 8 | C53: 763.96 | D53: C 775 2026-10-30 | E53: -1 | F53: 0.14707843 | G53: 2.74 | H53: -274 | J53: -27.167073 | K53: -1.9938003 | L53: 36.726888 | M53: -37.511896 | N53: mids
...
